Workbook

Sheet 00_Panduan
A1: Template Data Source - Strategi & Evaluasi
A2: Sumber | B2: Realisasi Bulanan RKM DIV GA 2026.xlsx
A3: Penggunaan | B3: Isi dan update tab 03_Kinerja untuk monitoring kinerja. Indikator disusun vertikal, periode Januari sampai Desember disusun ke kanan.
A4: Catatan | B4: Nilai realisasi mengikuti workbook RKM per baris. Format melebar ke kanan agar input bulanan tidak memanjang ke bawah.

Sheet 00_Referensi
A1: Kategori | B1: Nilai
A2: Status Kinerja | B2: Tercapai
A3: Status Kinerja | B3: Hampir Tercapai
A4: Status Kinerja | B4: Perlu Peningkatan
A5: Status Kinerja | B5: Belum Diukur
A6: Periode | B6: Januari
A7: Periode | B7: Februari
A8: Periode | B8: Maret
A9: Periode | B9: April
A10: Periode | B10: Mei
A11: Periode | B11: Juni
A12: Periode | B12: Juli
... A17: Periode | B17: Desember

Sheet 01_Ratifikasi
A1: Entitas SH/AP | B1: Kebijakan | C1: Status | D1: Catatan | E1: Last Update
A2: PLN IP | B2: Kebijakan Strategis Manajemen Aset Properti (Perdir No.0001.KS/DIR/2025) | C2: Selesai | D2: Diisi dari data ratifikasi dashboard | E2: 2026-09-02
A3: PLN IP | B3: Standar Prosedur Pendayagunaan Aset Properti (Perlak No.0004.SPo/DIR/2025) | C3: Selesai | D3: Diisi dari data ratifikasi dashboard | E3: 2026-09-02
A4: PLN IP | B4: Kebijakan Strategis Pengelolaan Naskah Dinas dan Kearsipan (Perdir No.0017.P/DIR/2023) | C4: Selesai | D4: Diisi dari data ratifikasi dashboard | E4: 2026-09-02
A5: PLN IP | B5: Standar Prosedur Pengelolaan Naskah Dinas (Perlak No.0016.E/DIR/2024) | C5: On Progress | D5: Diisi dari data ratifikasi dashboard | E5: 2026-09-02
A6: PLN IP | B6: Standar Prosedur Kearsipan PT PLN (Persero) (Perlak No.0017.E/DIR/2024) | C6: On Progress | D6: Diisi dari data ratifikasi dashboard | E6: 2026-09-02
A7: PLN IP | B7: Jadwal Retensi Arsip PT PLN (Persero) (Kepdir No. 0122.K/DIR/2024) | C7: On Progress | D7: Diisi dari data ratifikasi dashboard | E7: 2026-09-02
A8: PLN IP | B8: Sistem Klasifikasi Keamanan dan Akses Arsip Dinamis PT PLN (Persero) (Kepdir No. 0123.K/DIR/2024) | C8: On Progress | D8: Diisi dari data ratifikasi dashboard | E8: 2026-09-02
A9: PLN IP | B9: Standar Prosedur Perjalanan Dinas Pegawai (Perlak No.0036.E/DIR/2023) | C9: On Progress | D9: Diisi dari data ratifikasi dashboard | E9: 2026-09-02
A10: PLN IP | B10: Standar Prosedur Perjalanan Dinas (Juknis No.0021.I.DIR.2023) | C10: On Progress | D10: Diisi dari data ratifikasi dashboard | E10: 2026-09-02
A11: PLN IP | B11: Pelaksanaan Pemberian BFKO dan Bantuan Biaya Transportasi (Juknis No.0017.PTs/DIR/2025) | C11: On Progress | D11: Diisi dari data ratifikasi dashboard | E11: 2026-09-02
A12: PLN IP | B12: Penetapan Jenis, Pagu, dan Skema Pembayaran Kendaraan serta Besaran Biaya Dalam Rangka Pelaksanaan Pemberian BFKO dan Bantuan Biaya Transportasi (Kepdir No.0118.K/DIR/2025) | C12: On Progress | D12: Diisi dari data ratifikasi dashboard | E12: 2026-09-02
... A141: PLN EMI | B141: Indirect Procurement (Juknis No.0133.I/DIR/2024) | C141: Selesai | D141: Diisi dari data ratifikasi dashboard | E141: 2026-09-02

Sheet 02_Change_Request
A1: Aplikasi | B1: Change Request | C1: Progres | D1: Status | E1: Target Selesai | F1: Catatan | G1: Last Update
A2: ESPPD | B2: CR utama E-SPPD | C2: 66 | D2: On Progress | E2: Multi target | G2: 2026-09-02
A3: ESPPD Manage Service | B3: Integrasi manage service | C3: 100 | D3: Selesai | E3: 30 Jun 2026 | G3: 2026-09-02
A4: ESPPD Reengineering | B4: Re-Eng Tahap I | C4: 92 | D4: On Progress | E4: 46332 | G4: 2026-09-02
A5: ESPPD SHAP | B5: Pilot PLN EPI / SHAP | C5: 100 | D5: Selesai | E5: Sosialisasi | G5: 2026-09-02
A6: NEW E-COP | B6: Tahap I selesai, Tahap II 80% | C6: 100 | D6: Selesai | E6: 01 Oktober 2026 | G6: 2026-09-02
A7: E-COP PLN EPI | B7: Migrasi, approval, pemesanan kendaraan | C7: 79 | D7: On Progress | E7: To be confirmed | G7: 2026-09-02
A8: NEW E-MEETING PLN Click | B8: Integrasi E-Meeting dengan PLN Click | C8: 100 | D8: Selesai | E8: 23 Mei 2026 | G8: 2026-09-02
A9: E-MEETING Konsumsi Online | B9: Role, SIT, UAT, deploy | C9: 100 | D9: Selesai | E9: 05 Mei 2026 | G9: 2026-09-02
A10: E-TRANSPORT Multitrip | B10: Tahap I selesai, Tahap II belum berjalan | C10: 50 | D10: On Progress | E10: 15 Oktober 2026 | G10: 2026-09-02

Sheet 03_Kinerja
A1: Tahun | B1: No | C1: Indikator Kerja | D1: Satuan | E1: Bobot | F1: Target 2026 | G1: Catatan | H1: Last Update | I1: Baris RKM | J1: Januari Target Bulanan | K1: Januari Realisasi | L1: Januari Pencapaian | M1: Januari Nilai | N1: Januari Status | O1: Februari Target Bulanan | P1: Februari Realisasi | Q1: Februari Pencapaian | R1: Februari Nilai | S1: Februari Status | T1: Maret Target Bulanan | U1: Maret Realisasi | V1: Maret Pencapaian | W1: Maret Nilai | X1: Maret Status | Y1: April Target Bulanan | Z1: April Realisasi | AA1: April Pencapaian | AB1: April Nilai | AC1: April Status | AD1: Mei Target Bulanan | AE1: Mei Realisasi | AF1: Mei Pencapaian | AG1: Mei Nilai | AH1: Mei Status | AI1: Juni Target Bulanan | AJ1: Juni Realisasi | AK1: Juni Pencapaian | AL1: Juni Nilai | AM1: Juni Status | AN1: Juli Target Bulanan | AO1: Juli Realisasi | AP1: Juli Pencapaian | AQ1: Juli Nilai | AR1: Juli Status | AS1: Agustus Target Bulanan | AT1: Agustus Realisasi | AU1: Agustus Pencapaian | AV1: Agustus Nilai | AW1: Agustus Status | AX1: September Target Bulanan | AY1: September Realisasi | AZ1: September Pencapaian | BA1: September Nilai | BB1: September Status | BC1: Oktober Target Bulanan | BD1: Oktober Realisasi | BE1: Oktober Pencapaian | BF1: Oktober Nilai | BG1: Oktober Status | BH1: November Target Bulanan | BI1: November Realisasi | BJ1: November Pencapaian | BK1: November Nilai | BL1: November Status | BM1: Desember Target Bulanan | BN1: Desember Realisasi | BO1: Desember Pencapaian | BP1: Desember Nilai | BQ1: Desember Status
A2: 2026 | B2: 1 | C2: Efisiensi Biaya : | G2: Disalin dari indikator utama RKM. | H2: 2026-08-28 | I2: 15 | N2: Belum Diukur | S2: Belum Diukur | X2: Belum Diukur | AA2: 1.0706811 | AB2: 21.413622 | AC2: Tercapai | AF2: 1.08974 | AG2: 21.7948 | AH2: Tercapai | AK2: 1.1 | AL2: 22 | AM2: Tercapai | AP2: 1.1 | AQ2: 22 | AR2: Tercapai | AW2: Belum Diukur | BB2: Belum Diukur | BG2: Belum Diukur | BL2: Belum Diukur | BQ2: Belum Diukur
A3: 2026 | C3: a. Efektifitas Biaya Administrasi Umum | D3: Rp Miliar | E3: 14 | F3: 8856.162 | G3: Disalin dari subindikator RKM. | H3: 2026-08-28 | I3: 16 | J3: 714.83187 | N3: Belum Diukur | O3: 1330.7421 | S3: Belum Diukur | T3: 2100.3912 | X3: Belum Diukur | Y3: 2733.9227 | Z3: 2044.019 | AA3: 1.1 | AB3: 15.4 | AC3: Tercapai | AD3: 3562.0937 | AE3: 2711.064 | AF3: 1.1 | AG3: 15.4 | AH3: Tercapai | AI3: 4740.294 | AJ3: 3533.7626 | AK3: 1.1 | AL3: 15.4 | AM3: Tercapai | AN3: 5193.6355 | AO3: 4322.631 | AP3: 1.1 | AQ3: 15.4 | AR3: Tercapai | AS3: 5980.4787 | AW3: Belum Diukur | AX3: 6820.2642 | BB3: Belum Diukur | BC3: 7670.8338 | BG3: Belum Diukur | BH3: 8324.792 | BL3: Belum Diukur | BM3: 8856.162 | BQ3: Belum Diukur
A4: 2026 | C4: b. Pengendalian NAC (Non Allowable Cost) | D4: Rp Miliar | E4: 6 | F4: 283.17525 | G4: Disalin dari subindikator RKM. | H4: 2026-08-28 | I4: 17 | J4: 22.65402 | N4: Belum Diukur | O4: 42.476288 | S4: Belum Diukur | T4: 67.96206 | X4: Belum Diukur | Y4: 87.784328 | Z4: 87.585027 | AA4: 1.0022703 | AB4: 6.0136221 | AC4: Tercapai | AD4: 113.2701 | AE4: 105.81694 | AF4: 1.0657999 | AG4: 6.3947996 | AH4: Tercapai | AI4: 451.04055 | AJ4: 291.03527 | AK4: 1.1 | AL4: 6.6 | AM4: Tercapai | AN4: 517.21201 | AO4: 339.56028 | AP4: 1.1 | AQ4: 6.6 | AR4: Tercapai | AS4: 192.55917 | AW4: Belum Diukur | AX4: 218.04494 | BB4: Belum Diukur | BC4: 246.36247 | BG4: Belum Diukur | BH4: 266.18474 | BL4: Belum Diukur | BM4: 283.17525 | BQ4: Belum Diukur
A5: 2026 | B5: 2 | C5: Optimalisasi penggunaan aset tanah dan bangunan | D5: Rp Miliar | E5: 12 | F5: 147.7373 | G5: Disalin dari indikator utama RKM. | H5: 2026-08-28 | I5: 18 | J5: 5.9094728 | N5: Belum Diukur | O5: 9.2362515 | S5: Belum Diukur | T5: 11.818963 | X5: Belum Diukur | Y5: 48.753292 | Z5: 126.69479 | AA5: 1.1 | AB5: 13.2 | AC5: Tercapai | AD5: 53.924094 | AE5: 156.24434 | AF5: 1.1 | AG5: 13.2 | AH5: Tercapai | AI5: 59.833586 | AJ5: 91.211667 | AK5: 1.1 | AL5: 13.2 | AM5: Tercapai | AN5: 67.959138 | AO5: 94.902353 | AP5: 1.1 | AQ5: 13.2 | AR5: Tercapai | AS5: 79.778123 | AW5: Belum Diukur | AX5: 86.399624 | BB5: Belum Diukur | BC5: 95.991138 | BG5: Belum Diukur | BH5: 115.77011 | BL5: Belum Diukur | BM5: 147.7373 | BQ5: Belum Diukur
A6: 2026 | B6: 3 | C6: Penyediaan Dokumen Pengadaan Barang Jasa Kantor Pusat sampai dengan selesainya draft kontrak (Anggaran Operasi dan Investasi) | E6: 12 | G6: Disalin dari indikator utama RKM. | H6: 2026-08-28 | I6: 19 | N6: Belum Diukur | S6: Belum Diukur | X6: Belum Diukur | AA6: 1.0853014 | AB6: 13.023617 | AC6: Tercapai | AF6: 1.0853014 | AG6: 13.023617 | AH6: Tercapai | AK6: 1.0853014 | AL6: 13.023617 | AM6: Tercapai | AP6: 1.0598249 | AQ6: 12.717899 | AR6: Tercapai | AW6: Belum Diukur | BB6: Belum Diukur | BG6: Belum Diukur | BL6: Belum Diukur | BQ6: Belum Diukur
A7: 2026 | C7: a. Pengadaan Langsung / Penunjukan Langsung Pasca Kualifikasi | D7: % | F7: 93.96 | G7: Disalin dari subindikator RKM. | H7: 2026-08-28 | I7: 20 | J7: 93.96 | N7: Belum Diukur | O7: 93.96 | S7: Belum Diukur | T7: 93.96 | X7: Belum Diukur | Y7: 93.96 | Z7: 100 | AA7: 1.0642827 | AC7: Tercapai | AD7: 93.96 | AE7: 100 | AF7: 1.0642827 | AH7: Tercapai | AI7: 93.96 | AJ7: 100 | AK7: 1.0642827 | AM7: Tercapai | AN7: 93.96 | AO7: 95.74 | AP7: 1.0189442 | AR7: Tercapai | AS7: 93.96 | AW7: Belum Diukur | AX7: 93.96 | BB7: Belum Diukur | BC7: 93.96 | BG7: Belum Diukur | BH7: 93.96 | BL7: Belum Diukur | BM7: 93.96 | BQ7: Belum Diukur
A8: 2026 | C8: b. Penunjukan Langsung Pra Kualifikasi | D8: % | F8: 85.19 | G8: Disalin dari subindikator RKM. | H8: 2026-08-28 | I8: 21 | J8: 85.19 | N8: Belum Diukur | O8: 85.19 | S8: Belum Diukur | T8: 85.19 | X8: Belum Diukur | Y8: 85.19 | Z8: 100 | AA8: 1.1 | AC8: Tercapai | AD8: 85.19 | AE8: 100 | AF8: 1.1 | AH8: Tercapai | AI8: 85.19 | AJ8: 100 | AK8: 1.1 | AM8: Tercapai | AN8: 85.19 | AO8: 88.89 | AP8: 1.0434323 | AR8: Tercapai | AS8: 85.19 | AW8: Belum Diukur | AX8: 85.19 | BB8: Belum Diukur | BC8: 85.19 | BG8: Belum Diukur | BH8: 85.19 | BL8: Belum Diukur | BM8: 85.19 | BQ8: Belum Diukur
A9: 2026 | C9: c. Tender Terbuka (Pascakualifikasi) / Tender Terbatas (DPT/Shortlist) / Seleksi Umum (Pascakualifikasi) / Seleksi Terbatas (Pascakualifikasi) | D9: % | F9: 92.857143 | G9: Disalin dari subindikator RKM. | H9: 2026-08-28 | I9: 22 | J9: 92.857143 | N9: Belum Diukur | O9: 92.857143 | S9: Belum Diukur | T9: 92.857143 | X9: Belum Diukur | Y9: 92.857143 | Z9: 100 | AA9: 1.0769231 | AC9: Tercapai | AD9: 92.857143 | AE9: 100 | AF9: 1.0769231 | AH9: Tercapai | AI9: 92.857143 | AJ9: 100 | AK9: 1.0769231 | AM9: Tercapai | AN9: 92.857143 | AO9: 100 | AP9: 1.0769231 | AR9: Tercapai | AS9: 92.857143 | AW9: Belum Diukur | AX9: 92.857143 | BB9: Belum Diukur | BC9: 92.857143 | BG9: Belum Diukur | BH9: 92.857143 | BL9: Belum Diukur | BM9: 92.857143 | BQ9: Belum Diukur
A10: 2026 | C10: d. Seleksi Umum (Prakualifikasi) / Seleksi Terbatas (Prakualifikasi) / Tender Terbuka (Prakualifikasi) | D10: % | F10: 83.333333 | G10: Disalin dari subindikator RKM. | H10: 2026-08-28 | I10: 23 | J10: 83.333333 | N10: Belum Diukur | O10: 83.333333 | S10: Belum Diukur | T10: 83.333333 | X10: Belum Diukur | Y10: 83.333333 | Z10: 100 | AA10: 1.1 | AC10: Tercapai | AD10: 83.333333 | AE10: 100 | AF10: 1.1 | AH10: Tercapai | AI10: 83.333333 | AJ10: 100 | AK10: 1.1 | AM10: Tercapai | AN10: 83.333333 | AO10: 100 | AP10: 1.1 | AR10: Tercapai | AS10: 83.333333 | AW10: Belum Diukur | AX10: 83.333333 | BB10: Belum Diukur | BC10: 83.333333 | BG10: Belum Diukur | BH10: 83.333333 | BL10: Belum Diukur | BM10: 83.333333 | BQ10: Belum Diukur
A11: 2026 | B11: 4 | C11: Integrated GA Management System | E11: 12 | G11: Disalin dari indikator utama RKM. | H11: 2026-08-28 | I11: 24 | N11: Belum Diukur | S11: Belum Diukur | X11: Belum Diukur | AA11: 1 | AB11: 12 | AC11: Tercapai | AF11: 1 | AG11: 12 | AH11: Tercapai | AM11: Belum Diukur | AP11: 1.0023 | AQ11: 12.0276 | AR11: Tercapai | AW11: Belum Diukur | BB11: Belum Diukur | BG11: Belum Diukur | BL11: Belum Diukur | BQ11: Belum Diukur
A12: 2026 | C12: a. Optimalisasi penyerapan anggaran pemeliharaan sarana terkonsolidasi | D12: % | F12: 95-100 | G12: Disalin dari subindikator RKM. | H12: 2026-08-28 | I12: 25 | J12: 95-100 | N12: Belum Diukur | O12: 95-100 | S12: Belum Diukur | T12: 95-100 | X12: Belum Diukur | Y12: 95-100 | Z12: 100 | AA12: 1 | AC12: Tercapai | AD12: 95-100 | AE12: 100 | AF12: 1 | AH12: Tercapai | AI12: 95-100 | AJ12: 0 | AK12: -0.9 | AM12: Perlu Peningkatan | AN12: 95-100 | AO12: 95.23 | AP12: 1.0046 | AR12: Tercapai | AS12: 95-100 | AW12: Belum Diukur | AX12: 95-100 | BB12: Belum Diukur | BC12: 95-100 | BG12: Belum Diukur | BH12: 95-100 | BL12: Belum Diukur | BM12: 95-100 | BQ12: Belum Diukur
A13: 2026 | C13: b. Pengembangan Aplikasi Transformasi GA : | D13: Waktu | F13: 31 Desember 2026 | G13: Disalin dari subindikator RKM. | H13: 2026-08-28 | I13: 26 | J13: 1. Laporan progres pengembangan aplikasi 2. Laporan progres pengembangan aplikasi | N13: Belum Diukur | O13: 1. Laporan progres pengembangan aplikasi 2. Laporan progres pengembangan aplikasi | S13: Belum Diukur | T13: 1. Laporan progres pengembangan aplikasi 2. Laporan progres pengembangan aplikasi | X13: Belum Diukur | Y13: 1. Laporan progres pengembangan aplikasi 2. Laporan progres pengembangan aplikasi | Z13: 1. Laporan progres pengembangan aplikasi 2. Laporan progres pengembangan aplikasi | AA13: 1 | AC13: Tercapai | AD13: 1. Laporan progres pengembangan aplikasi 2. BA UAT change request aplikasi E-Meeting | AE13: 1. Laporan progres pengembangan aplikasi 2. BA UAT change request aplikasi E-Meeting | AF13: 1 | AH13: Tercapai | AI13: 46203 | AJ13: 46172 | AM13: Belum Diukur | AN13: 1. Laporan progres pengembangan aplikasi 2. Laporan progres pengembangan aplikasi | AO13: 1. Laporan progres pengembangan aplikasi 2. Laporan progres pengembangan aplikasi | AP13: 1 | AR13: Tercapai | AS13: 1. Laporan progres pengembangan aplikasi 2. Laporan progres pengembangan aplikasi | AW13: Belum Diukur | AX13: 1. Laporan progres pengembangan aplikasi 2. Laporan progres pengembangan aplikasi | BB13: Belum Diukur | BC13: 1. Laporan progres pengembangan aplikasi 2. Laporan progres pengembangan aplikasi | BG13: Belum Diukur | BH13: 1. Laporan progres pengembangan aplikasi 2. BA UAT change request aplikasi perjalanan dinas | BL13: Belum Diukur | BM13: 1. BA Go Live integrasi DSA dengan 1 aplikasi surrounding SSOT 2. BA Deployment change request aplikasi perjalanan dinas | BQ13: Belum Diukur
A14: 2026 | B14: 5 | C14: Penyusunan Kebijakan General Affair | D14: Waktu | E14: 12 | F14: 31 Desember 2026 | G14: Disalin dari indikator utama RKM. | H14: 2026-08-28 | I14: 27 | J14: Pengumpulan dokumen dan literatur sebagai bahan FGD Internal penyusunan kebijakan | N14: Belum Diukur | O14: Pengumpulan dokumen dan literatur sebagai bahan FGD Internal penyusunan kebijakan | S14: Belum Diukur | T14: Pengumpulan dokumen dan literatur sebagai bahan FGD Internal penyusunan kebijakan | X14: Belum Diukur | Y14: FGD Internal penyusunan kebijakan | Z14: FGD Internal penyusunan kebijakan | AA14: 1 | AB14: 12 | AC14: Tercapai | AD14: Penyusunan Draft Usulan kebijakan | AE14: Penyusunan Draft Usulan kebijakan | AF14: 1 | AG14: 12 | AH14: Tercapai | AI14: 46203 | AJ14: 46139 | AM14: Belum Diukur | AN14: Pembahasan dengan Divisi Terkait | AO14: Pembahasan dengan Divisi Terkait | AP14: 1 | AQ14: 12 | AR14: Tercapai | AS14: Pembahasan dengan Divisi Terkait | AW14: Belum Diukur | AX14: Pembahasan dengan Divisi Terkait | BB14: Belum Diukur | BC14: Pembahasan dengan Divisi Terkait | BG14: Belum Diukur | BH14: Finalisasi draft kebijakan | BL14: Belum Diukur | BM14: Dokumen kebijakan yang ditandatangani oleh Direksi | BQ14: Belum Diukur
A15: 2026 | B15: 6 | C15: Proses Sentralisasi Pembayaran | D15: % | E15: 10 | F15: 93.92 | G15: Disalin dari indikator utama RKM. | H15: 2026-08-28 | I15: 28 | J15: 93.92 | N15: Belum Diukur | O15: 93.92 | S15: Belum Diukur | T15: 93.92 | X15: Belum Diukur | Y15: 93.92 | Z15: 94 | AA15: 1.0008518 | AB15: 10.008518 | AC15: Tercapai | AD15: 93.92 | AE15: 95 | AF15: 1.0114991 | AG15: 10.114991 | AH15: Tercapai | AI15: 93.92 | AJ15: 93.8 | AK15: 0.99872232 | AL15: 9.9872232 | AM15: Hampir Tercapai | AN15: 93.92 | AO15: 93.88 | AP15: 0.99957411 | AQ15: 9.9957411 | AR15: Hampir Tercapai | AS15: 93.92 | AW15: Belum Diukur | AX15: 93.92 | BB15: Belum Diukur | BC15: 93.92 | BG15: Belum Diukur | BH15: 93.92 | BL15: Belum Diukur | BM15: 93.92 | BQ15: Belum Diukur
A16: 2026 | B16: 7 | C16: Manajemen Kearsipan | D16: % | E16: 10 | F16: 95 | G16: Disalin dari indikator utama RKM. | H16: 2026-08-28 | I16: 29 | J16: NA | N16: Belum Diukur | O16: NA | S16: Belum Diukur | T16: NA | X16: Belum Diukur | Y16: 95 | Z16: 95 | AA16: 1 | AB16: 10 | AC16: Tercapai | AD16: 95 | AE16: 95 | AF16: 1 | AG16: 10 | AH16: Tercapai | AI16: 95 | AJ16: 105.61 | AK16: 1.1 | AL16: 11 | AM16: Tercapai | AN16: 95 | AO16: 95 | AP16: 1 | AQ16: 10 | AR16: Tercapai | AS16: 95 | AW16: Belum Diukur | AX16: 95 | BB16: Belum Diukur | BC16: 95 | BG16: Belum Diukur | BH16: 95 | BL16: Belum Diukur | BM16: 95 | BQ16: Belum Diukur
A17: 2026 | B17: 8 | C17: Implementasi smart and green building | D17: SM 1 : Waktu SM 2 : Unit | E17: 6 | F17: 7 | G17: Disalin dari indikator utama RKM. | H17: 2026-08-28 | I17: 30 | J17: Surat Layanan Manage Service Implementasi Smart and Green Building | N17: Belum Diukur | O17: Penyusunan KAK | S17: Belum Diukur | T17: ND Pengadaan | X17: Belum Diukur | Y17: Proses Pengadaan | Z17: Proses Pengadaan | AA17: 1 | AB17: 6 | AC17: Tercapai | AD17: Kontrak KHS | AE17: Kontrak KHS | AF17: 1 | AG17: 6 | AH17: Tercapai | AI17: 46173 | AJ17: 46163 | AK17: 1.0142857 | AL17: 6.0857143 | AM17: Tercapai | AN17: Audit Energi | AO17: Audit Energi | AP17: 1 | AQ17: 6 | AR17: Tercapai | AS17: Audit Energi | AW17: Belum Diukur | AX17: Laporan Progres Fisik | BB17: Belum Diukur | BC17: Laporan Progres Fisik | BG17: Belum Diukur | BH17: Laporan Progres Fisik | BL17: Belum Diukur | BM17: 7 | BQ17: Belum Diukur
A18: 2026 | B18: 9 | C18: Usulan Anggaran Investasi Non Infrastruktur Ketenagalistrikan-Sarana Prasarana Umum untuk Tahun 2026 | D18: % | E18: 6 | F18: 100 | G18: Disalin dari indikator utama RKM. | H18: 2026-08-28 | I18: 31 | J18: 100 | N18: Belum Diukur | O18: 100 | S18: Belum Diukur | T18: 100 | X18: Belum Diukur | Y18: 100 | Z18: 100 | AA18: 1 | AB18: 6 | AC18: Tercapai | AD18: 100 | AE18: 100 | AF18: 1 | AG18: 6 | AH18: Tercapai | AI18: 100 | AJ18: 100 | AK18: 1 | AL18: 6 | AM18: Tercapai | AN18: 100 | AO18: 100 | AP18: 1 | AQ18: 6 | AR18: Tercapai | AS18: 100 | AW18: Belum Diukur | AX18: 100 | BB18: Belum Diukur | BC18: 100 | BG18: Belum Diukur | BH18: 100 | BL18: Belum Diukur | BM18: 100 | BQ18: Belum Diukur
A19: 2026 | B19: 10 | C19: Kepatuhan, Maturity Level dan Tata Kelola Perusahaan | G19: Disalin dari indikator utama RKM. | H19: 2026-08-28 | I19: 32 | N19: Belum Diukur | S19: Belum Diukur | X19: Belum Diukur | AC19: Belum Diukur | AH19: Belum Diukur | AM19: Belum Diukur | AR19: Belum Diukur | AW19: Belum Diukur | BB19: Belum Diukur | BG19: Belum Diukur | BL19: Belum Diukur | BQ19: Belum Diukur
A20: 2026 | C20: a. Implementasi Maturity Level | E20: Max -2 | G20: Disalin dari subindikator RKM. | H20: 2026-08-28 | I20: 33 | N20: Belum Diukur | S20: Belum Diukur | X20: Belum Diukur | AC20: Belum Diukur | AH20: Belum Diukur | AM20: Belum Diukur | AR20: Belum Diukur | AW20: Belum Diukur | BB20: Belum Diukur | BG20: Belum Diukur | BL20: Belum Diukur | BQ20: Belum Diukur
A21: 2026 | C21: b. Kepatuhan | E21: Max -3 | G21: Disalin dari subindikator RKM. | H21: 2026-08-28 | I21: 34 | N21: Belum Diukur | S21: Belum Diukur | X21: Belum Diukur | AC21: Belum Diukur | AH21: Belum Diukur | AM21: Belum Diukur | AR21: Belum Diukur | AW21: Belum Diukur | BB21: Belum Diukur | BG21: Belum Diukur | BL21: Belum Diukur | BQ21: Belum Diukur
A22: 2026 | C22: c. Tata Kelola Perusahaan | E22: Max -1 | G22: Disalin dari subindikator RKM. | H22: 2026-08-28 | I22: 35 | N22: Belum Diukur | S22: Belum Diukur | X22: Belum Diukur | AC22: Belum Diukur | AH22: Belum Diukur | AM22: Belum Diukur | AR22: Belum Diukur | AW22: Belum Diukur | BB22: Belum Diukur | BG22: Belum Diukur | BL22: Belum Diukur | BQ22: Belum Diukur

Sheet 04_Penyusunan_Kebijakan
A1: No | B1: Bidang | C1: Lingkup | D1: Progres | E1: Status | F1: Target | G1: Catatan | H1: Last Update
A2: 1 | B2: Fasilitas | C2: Petunjuk Teknis Fasilitas Komunikasi | D2: 81 | E2: On Progress | F2: 31 Juli 2026 | H2: 2026-09-02
A3: 2 | B3: Fasilitas | C3: Petunjuk Teknis BFKO | D3: 81 | E3: On Progress | F3: 31 Juli 2026 | H3: 2026-09-02
A4: 3 | B4: ATK | C4: Petunjuk Teknis Pengelolaan ATK | D4: 10 | E4: On Progress | F4: 31 Okt 2026 | H4: 2026-09-02

Sheet 05_Business_Excellence
A1: Semester | B1: Aktivitas | C1: Target | D1: Realisasi | E1: Status | F1: Catatan | G1: Last Update
A2: Semester 1 | B2: Penyusunan dan updating dokumen aplikasi | C2: 100 | D2: 100.18 | E2: Tercapai | G2: 2026-09-02
A3: Semester 2 | B3: Pencapaian update dokumen dan asesmen nilai skor PLN Bisnis Ekselen | C3: 100 | D3: Belum Dinilai | E3: Belum Ukur | G3: 2026-09-02

Sheet 09_Ringkasan
A1: Periode | B1: Tahun | C1: Indikator | D1: Rumus/Nilai | E1: Nilai Validasi | F1: Catatan
A2: Januari | B2: 2026 | C2: Nilai NKO | D2: =IFERROR(SUMPRODUCT(--ISNUMBER('03_Kinerja'!M2:M22),'03_Kinerja'!M2:M22)*100/SUMPRODUCT(--ISNUMBER('03_Kinerja'!M2:M22),'03_Kinerja'!E2:E22),"") | F2: Formula: total Nilai periode / total Bobot indikator yang memiliki Nilai x 100.
A3: Januari | B3: 2026 | C3: Total Indikator | D3: =COUNTA('03_Kinerja'!B2:B22) -> 10 | E3: 10 | F3: Jumlah indikator utama RKM pada periode berjalan.
A4: Januari | B4: 2026 | C4: Indikator Tercapai | D4: =COUNTIFS('03_Kinerja'!B2:B22,"<>",'03_Kinerja'!N2:N22,"Tercapai") -> 0 | E4: 0 | F4: Indikator dengan pencapaian >= 100% atau status Tercapai.
A5: Januari | B5: 2026 | C5: Indikator Hampir Tercapai | D5: =COUNTIFS('03_Kinerja'!B2:B22,"<>",'03_Kinerja'!N2:N22,"Hampir Tercapai") -> 0 | E5: 0 | F5: Indikator dengan pencapaian 95% sampai kurang dari 100%.
A6: Januari | B6: 2026 | C6: Indikator Tidak Tercapai | D6: =COUNTIFS('03_Kinerja'!B2:B22,"<>",'03_Kinerja'!N2:N22,"Perlu Peningkatan") -> 0 | E6: 0 | F6: Indikator dengan pencapaian kurang dari 95%.
A7: Januari | B7: 2026 | C7: Indikator Belum Diukur | D7: =COUNTIFS('03_Kinerja'!B2:B22,"<>",'03_Kinerja'!N2:N22,"Belum Diukur") -> 10 | E7: 10 | F7: Indikator yang belum memiliki nilai/pengukuran pada periode berjalan.
A8: Februari | B8: 2026 | C8: Nilai NKO | D8: =IFERROR(SUMPRODUCT(--ISNUMBER('03_Kinerja'!R2:R22),'03_Kinerja'!R2:R22)*100/SUMPRODUCT(--ISNUMBER('03_Kinerja'!R2:R22),'03_Kinerja'!E2:E22),"") | F8: Formula: total Nilai periode / total Bobot indikator yang memiliki Nilai x 100.
A9: Februari | B9: 2026 | C9: Total Indikator | D9: =COUNTA('03_Kinerja'!B2:B22) -> 10 | E9: 10 | F9: Jumlah indikator utama RKM pada periode berjalan.
A10: Februari | B10: 2026 | C10: Indikator Tercapai | D10: =COUNTIFS('03_Kinerja'!B2:B22,"<>",'03_Kinerja'!S2:S22,"Tercapai") -> 0 | E10: 0 | F10: Indikator dengan pencapaian >= 100% atau status Tercapai.
A11: Februari | B11: 2026 | C11: Indikator Hampir Tercapai | D11: =COUNTIFS('03_Kinerja'!B2:B22,"<>",'03_Kinerja'!S2:S22,"Hampir Tercapai") -> 0 | E11: 0 | F11: Indikator dengan pencapaian 95% sampai kurang dari 100%.
A12: Februari | B12: 2026 | C12: Indikator Tidak Tercapai | D12: =COUNTIFS('03_Kinerja'!B2:B22,"<>",'03_Kinerja'!S2:S22,"Perlu Peningkatan") -> 0 | E12: 0 | F12: Indikator dengan pencapaian kurang dari 95%.
A13: Februari | B13: 2026 | C13: Indikator Belum Diukur | D13: =COUNTIFS('03_Kinerja'!B2:B22,"<>",'03_Kinerja'!S2:S22,"Belum Diukur") -> 10 | E13: 10 | F13: Indikator yang belum memiliki nilai/pengukuran pada periode berjalan.
A14: Maret | B14: 2026 | C14: Nilai NKO | D14: =IFERROR(SUMPRODUCT(--ISNUMBER('03_Kinerja'!W2:W22),'03_Kinerja'!W2:W22)*100/SUMPRODUCT(--ISNUMBER('03_Kinerja'!W2:W22),'03_Kinerja'!E2:E22),"") | F14: Formula: total Nilai periode / total Bobot indikator yang memiliki Nilai x 100.
A15: Maret | B15: 2026 | C15: Total Indikator | D15: =COUNTA('03_Kinerja'!B2:B22) -> 10 | E15: 10 | F15: Jumlah indikator utama RKM pada periode berjalan.
A16: Maret | B16: 2026 | C16: Indikator Tercapai | D16: =COUNTIFS('03_Kinerja'!B2:B22,"<>",'03_Kinerja'!X2:X22,"Tercapai") -> 0 | E16: 0 | F16: Indikator dengan pencapaian >= 100% atau status Tercapai.
A17: Maret | B17: 2026 | C17: Indikator Hampir Tercapai | D17: =COUNTIFS('03_Kinerja'!B2:B22,"<>",'03_Kinerja'!X2:X22,"Hampir Tercapai") -> 0 | E17: 0 | F17: Indikator dengan pencapaian 95% sampai kurang dari 100%.
A18: Maret | B18: 2026 | C18: Indikator Tidak Tercapai | D18: =COUNTIFS('03_Kinerja'!B2:B22,"<>",'03_Kinerja'!X2:X22,"Perlu Peningkatan") -> 0 | E18: 0 | F18: Indikator dengan pencapaian kurang dari 95%.
A19: Maret | B19: 2026 | C19: Indikator Belum Diukur | D19: =COUNTIFS('03_Kinerja'!B2:B22,"<>",'03_Kinerja'!X2:X22,"Belum Diukur") -> 10 | E19: 10 | F19: Indikator yang belum memiliki nilai/pengukuran pada periode berjalan.
A20: April | B20: 2026 | C20: Nilai NKO | D20: =IFERROR(SUMPRODUCT(--ISNUMBER('03_Kinerja'!AB2:AB22),'03_Kinerja'!AB2:AB22)*100/SUMPRODUCT(--ISNUMBER('03_Kinerja'!AB2:AB22),'03_Kinerja'!E2:E22),"") -> 125.05938 | E20: 103.64576 | F20: Formula: total Nilai periode / total Bobot indikator yang memiliki Nilai x 100.
A21: April | B21: 2026 | C21: Total Indikator | D21: =COUNTA('03_Kinerja'!B2:B22) -> 10 | E21: 10 | F21: Jumlah indikator utama RKM pada periode berjalan.
A22: April | B22: 2026 | C22: Indikator Tercapai | D22: =COUNTIFS('03_Kinerja'!B2:B22,"<>",'03_Kinerja'!AC2:AC22,"Tercapai") -> 9 | E22: 9 | F22: Indikator dengan pencapaian >= 100% atau status Tercapai.
A23: April | B23: 2026 | C23: Indikator Hampir Tercapai | D23: =COUNTIFS('03_Kinerja'!B2:B22,"<>",'03_Kinerja'!AC2:AC22,"Hampir Tercapai") -> 0 | E23: 0 | F23: Indikator dengan pencapaian 95% sampai kurang dari 100%.
A24: April | B24: 2026 | C24: Indikator Tidak Tercapai | D24: =COUNTIFS('03_Kinerja'!B2:B22,"<>",'03_Kinerja'!AC2:AC22,"Perlu Peningkatan") -> 0 | E24: 0 | F24: Indikator dengan pencapaian kurang dari 95%.
A25: April | B25: 2026 | C25: Indikator Belum Diukur | D25: =COUNTIFS('03_Kinerja'!B2:B22,"<>",'03_Kinerja'!AC2:AC22,"Belum Diukur") -> 1 | E25: 1 | F25: Indikator yang belum memiliki nilai/pengukuran pada periode berjalan.
A26: Mei | B26: 2026 | C26: Nilai NKO | D26: =IFERROR(SUMPRODUCT(--ISNUMBER('03_Kinerja'!AG2:AG22),'03_Kinerja'!AG2:AG22)*100/SUMPRODUCT(--ISNUMBER('03_Kinerja'!AG2:AG22),'03_Kinerja'!E2:E22),"") -> 125.92821 | E26: 104.13341 | F26: Formula: total Nilai periode / total Bobot indikator yang memiliki Nilai x 100.
A27: Mei | B27: 2026 | C27: Total Indikator | D27: =COUNTA('03_Kinerja'!B2:B22) -> 10 | E27: 10 | F27: Jumlah indikator utama RKM pada periode berjalan.
A28: Mei | B28: 2026 | C28: Indikator Tercapai | D28: =COUNTIFS('03_Kinerja'!B2:B22,"<>",'03_Kinerja'!AH2:AH22,"Tercapai") -> 9 | E28: 9 | F28: Indikator dengan pencapaian >= 100% atau status Tercapai.
A29: Mei | B29: 2026 | C29: Indikator Hampir Tercapai | D29: =COUNTIFS('03_Kinerja'!B2:B22,"<>",'03_Kinerja'!AH2:AH22,"Hampir Tercapai") -> 0 | E29: 0 | F29: Indikator dengan pencapaian 95% sampai kurang dari 100%.
A30: Mei | B30: 2026 | C30: Indikator Tidak Tercapai | D30: =COUNTIFS('03_Kinerja'!B2:B22,"<>",'03_Kinerja'!AH2:AH22,"Perlu Peningkatan") -> 0 | E30: 0 | F30: Indikator dengan pencapaian kurang dari 95%.
A31: Mei | B31: 2026 | C31: Indikator Belum Diukur | D31: =COUNTIFS('03_Kinerja'!B2:B22,"<>",'03_Kinerja'!AH2:AH22,"Belum Diukur") -> 1 | E31: 1 | F31: Indikator yang belum memiliki nilai/pengukuran pada periode berjalan.
A32: Juni | B32: 2026 | C32: Nilai NKO | D32: =IFERROR(SUMPRODUCT(--ISNUMBER('03_Kinerja'!AL2:AL22),'03_Kinerja'!AL2:AL22)*100/SUMPRODUCT(--ISNUMBER('03_Kinerja'!AL2:AL22),'03_Kinerja'!E2:E22),"") -> 135.91652 | E32: 106.96915 | F32: Formula: total Nilai periode / total Bobot indikator yang memiliki Nilai x 100.
A33: Juni | B33: 2026 | C33: Total Indikator | D33: =COUNTA('03_Kinerja'!B2:B22) -> 10 | E33: 10 | F33: Jumlah indikator utama RKM pada periode berjalan.
A34: Juni | B34: 2026 | C34: Indikator Tercapai | D34: =COUNTIFS('03_Kinerja'!B2:B22,"<>",'03_Kinerja'!AM2:AM22,"Tercapai") -> 6 | E34: 6 | F34: Indikator dengan pencapaian >= 100% atau status Tercapai.
A35: Juni | B35: 2026 | C35: Indikator Hampir Tercapai | D35: =COUNTIFS('03_Kinerja'!B2:B22,"<>",'03_Kinerja'!AM2:AM22,"Hampir Tercapai") -> 1 | E35: 1 | F35: Indikator dengan pencapaian 95% sampai kurang dari 100%.
A36: Juni | B36: 2026 | C36: Indikator Tidak Tercapai | D36: =COUNTIFS('03_Kinerja'!B2:B22,"<>",'03_Kinerja'!AM2:AM22,"Perlu Peningkatan") -> 0 | E36: 0 | F36: Indikator dengan pencapaian kurang dari 95%.
A37: Juni | B37: 2026 | C37: Indikator Belum Diukur | D37: =COUNTIFS('03_Kinerja'!B2:B22,"<>",'03_Kinerja'!AM2:AM22,"Belum Diukur") -> 3 | E37: 3 | F37: Indikator yang belum memiliki nilai/pengukuran pada periode berjalan.
A38: Juli | B38: 2026 | C38: Nilai NKO | D38: =IFERROR(SUMPRODUCT(--ISNUMBER('03_Kinerja'!AQ2:AQ22),'03_Kinerja'!AQ2:AQ22)*100/SUMPRODUCT(--ISNUMBER('03_Kinerja'!AQ2:AQ22),'03_Kinerja'!E2:E22),"") -> 125.94124 | E38: 103.94124 | F38: Formula: total Nilai periode / total Bobot indikator yang memiliki Nilai x 100.
A39: Juli | B39: 2026 | C39: Total Indikator | D39: =COUNTA('03_Kinerja'!B2:B22) -> 10 | E39: 10 | F39: Jumlah indikator utama RKM pada periode berjalan.
A40: Juli | B40: 2026 | C40: Indikator Tercapai | D40: =COUNTIFS('03_Kinerja'!B2:B22,"<>",'03_Kinerja'!AR2:AR22,"Tercapai") -> 8 | E40: 8 | F40: Indikator dengan pencapaian >= 100% atau status Tercapai.
...
